<?xml version="1.0" ?>
<sdf version="1.8">
  <model name="drone_cvar_racing">
    <link name="base_link">
      <enable_wind>true</enable_wind>
        <pose>0 0 0 0 -0 0</pose>
        <inertial>
        <pose>0 0 0 0 -0 0</pose>
        <mass>0.988</mass>
        <inertia>
            <ixx>0.0032384</ixx>
            <ixy>0</ixy>
            <ixz>0</ixz>
            <iyy>0.0040254</iyy>
            <iyz>0</iyz>
            <izz>0.00459895</izz>
        </inertia>
        </inertial>
      <visual name="base_link_visual">
        <pose>-0.06 0.007 0.001 0.0 0.0 0.0</pose>
        <geometry>
          <mesh>
            <uri>model://drone_cvar_racing/meshes/drone_cvar_racing.dae</uri>
          </mesh>
        </geometry>
        <material>
          <diffuse>1.0 1.0 1.0 1.0</diffuse>
          <specular>0.0 0.0 0.0 1.0</specular>
          <pbr>
            <metal/>
          </pbr>
        </material>
      </visual>
      <!-- <collision name="collision">
        <geometry>
          <mesh>
            <uri>meshes/drone_cvar_racing.dae</uri>
          </mesh>
        </geometry>
        <surface>
          <contact>
            <collide_bitmask>0x01</collide_bitmask>
          </contact>
        </surface>
      </collision> -->
      <collision name='base_link_inertia_collision'>
        <pose>0 0 0.0 0 -0 0</pose>
        <geometry>
            <box>
            <size>0.35 0.30 0.15</size>
            </box>
        </geometry>
      </collision>
    </link>

    <!-- IMU -->
    <model name='imu'>
        <link name="internal">
            <inertial>
                <mass>0.005</mass>
                <inertia>
                    <ixx>8.33e-06</ixx>
                    <ixy>0</ixy>
                    <ixz>0</ixz>
                    <iyy>8.33e-06</iyy>
                    <iyz>0</iyz>
                    <izz>8.33e-06</izz>
                </inertia>
            </inertial>
            <sensor name='imu' type='imu'>
                <always_on>1</always_on>
                <update_rate>200</update_rate>
                <imu>
                    <angular_velocity>
                        <x>
                            <!-- [1] mid-grade MEMS (original ~ICM-20689) -->
                            <noise type='gaussian'>
                                <mean>0</mean>
                                <stddev>0.0001331581</stddev>
                                <bias_mean>0.0075</bias_mean>
                                <bias_stddev>3.25989553e-4</bias_stddev>
                                <dynamic_bias_stddev>0.00001</dynamic_bias_stddev>
                                <dynamic_bias_correlation_time>200.0</dynamic_bias_correlation_time>
                            </noise>
                            <!-- [3] perfect IMU (no noise) -->
                            <!-- <noise type='none'/> -->
                            <!-- [2] low-noise MEMS (active, ~VectorNav VN-100) -->
                            <!-- <noise type='gaussian'>
                                <mean>0</mean>
                                <stddev>0.00004</stddev>
                                <bias_mean>0.002</bias_mean>
                                <bias_stddev>1.0e-4</bias_stddev>
                                <dynamic_bias_stddev>0.000004</dynamic_bias_stddev>
                                <dynamic_bias_correlation_time>400.0</dynamic_bias_correlation_time>
                            </noise> -->
                        </x>
                        <y>
                            <!-- [1] mid-grade MEMS (original ~ICM-20689) -->
                            <noise type='gaussian'>
                                <mean>0</mean>
                                <stddev>0.0001331581</stddev>
                                <bias_mean>0.0075</bias_mean>
                                <bias_stddev>3.25989553e-4</bias_stddev>
                                <dynamic_bias_stddev>0.00001</dynamic_bias_stddev>
                                <dynamic_bias_correlation_time>200.0</dynamic_bias_correlation_time>
                            </noise>
                            <!-- [3] perfect IMU (no noise) -->
                            <!-- <noise type='none'/> -->
                            <!-- [2] low-noise MEMS (active, ~VectorNav VN-100) -->
                            <!-- <noise type='gaussian'>
                                <mean>0</mean>
                                <stddev>0.00004</stddev>
                                <bias_mean>0.002</bias_mean>
                                <bias_stddev>1.0e-4</bias_stddev>
                                <dynamic_bias_stddev>0.000004</dynamic_bias_stddev>
                                <dynamic_bias_correlation_time>400.0</dynamic_bias_correlation_time>
                            </noise> -->
                        </y>
                        <z>
                            <!-- [1] mid-grade MEMS (original ~ICM-20689) -->
                            <noise type='gaussian'>
                                <mean>0</mean>
                                <stddev>0.0001331581</stddev>
                                <bias_mean>0.0075</bias_mean>
                                <bias_stddev>3.25989553e-4</bias_stddev>
                                <dynamic_bias_stddev>0.00001</dynamic_bias_stddev>
                                <dynamic_bias_correlation_time>200.0</dynamic_bias_correlation_time>
                            </noise>
                            <!-- [3] perfect IMU (no noise) -->
                            <!-- <noise type='none'/> -->
                            <!-- [2] low-noise MEMS (active, ~VectorNav VN-100) -->
                            <!-- <noise type='gaussian'>
                                <mean>0</mean>
                                <stddev>0.00004</stddev>
                                <bias_mean>0.002</bias_mean>
                                <bias_stddev>1.0e-4</bias_stddev>
                                <dynamic_bias_stddev>0.000004</dynamic_bias_stddev>
                                <dynamic_bias_correlation_time>400.0</dynamic_bias_correlation_time>
                            </noise> -->
                        </z>
                    </angular_velocity>
                    <linear_acceleration>
                        <x>
                            <!-- [1] mid-grade MEMS (original ~ICM-20689) -->
                            <noise type='gaussian'>
                                <mean>0</mean>
                                <stddev>0.0336588782</stddev>
                                <bias_mean>0.1</bias_mean>
                                <bias_stddev>0.006676</bias_stddev>
                                <dynamic_bias_stddev>0.000375</dynamic_bias_stddev>
                                <dynamic_bias_correlation_time>150.0</dynamic_bias_correlation_time>
                            </noise>
                            <!-- [3] perfect IMU (no noise) -->
                            <!-- <noise type='none'/> -->
                            <!-- [2] low-noise MEMS (active, ~VectorNav VN-100) -->
                            <!-- <noise type='gaussian'>
                                <mean>0</mean>
                                <stddev>0.01</stddev>
                                <bias_mean>0.03</bias_mean>
                                <bias_stddev>0.002</bias_stddev>
                                <dynamic_bias_stddev>0.0001</dynamic_bias_stddev>
                                <dynamic_bias_correlation_time>300.0</dynamic_bias_correlation_time>
                            </noise> -->
                        </x>
                        <y>
                            <!-- [1] mid-grade MEMS (original ~ICM-20689) -->
                            <noise type='gaussian'>
                                <mean>0</mean>
                                <stddev>0.0336588782</stddev>
                                <bias_mean>0.1</bias_mean>
                                <bias_stddev>0.006676</bias_stddev>
                                <dynamic_bias_stddev>0.000375</dynamic_bias_stddev>
                                <dynamic_bias_correlation_time>150.0</dynamic_bias_correlation_time>
                            </noise>
                            <!-- [3] perfect IMU (no noise) -->
                            <!-- <noise type='none'/> -->
                            <!-- [2] low-noise MEMS (active, ~VectorNav VN-100) -->
                            <!-- <noise type='gaussian'>
                                <mean>0</mean>
                                <stddev>0.01</stddev>
                                <bias_mean>0.03</bias_mean>
                                <bias_stddev>0.002</bias_stddev>
                                <dynamic_bias_stddev>0.0001</dynamic_bias_stddev>
                                <dynamic_bias_correlation_time>300.0</dynamic_bias_correlation_time>
                            </noise> -->
                        </y>
                        <z>
                            <!-- [1] mid-grade MEMS (original ~ICM-20689) -->
                            <noise type='gaussian'>
                                <mean>0</mean>
                                <stddev>0.0336588782</stddev>
                                <bias_mean>0.1</bias_mean>
                                <bias_stddev>0.006676</bias_stddev>
                                <dynamic_bias_stddev>0.000375</dynamic_bias_stddev>
                                <dynamic_bias_correlation_time>150.0</dynamic_bias_correlation_time>
                            </noise>
                            <!-- [3] perfect IMU (no noise) -->
                            <!-- <noise type='none'/> -->
                            <!-- [2] low-noise MEMS (active, ~VectorNav VN-100) -->
                            <!-- <noise type='gaussian'>
                                <mean>0</mean>
                                <stddev>0.01</stddev>
                                <bias_mean>0.03</bias_mean>
                                <bias_stddev>0.002</bias_stddev>
                                <dynamic_bias_stddev>0.0001</dynamic_bias_stddev>
                                <dynamic_bias_correlation_time>300.0</dynamic_bias_correlation_time>
                            </noise> -->
                        </z>
                    </linear_acceleration>
                </imu>
            </sensor>
        </link>
    </model>

    <joint name="imu_joint" type="fixed">
        <parent>base_link</parent>
        <child>imu</child>
    </joint>

    <link name='rotor_0'>
        <pose>0.143513952 -0.104268989 0.0 0 -0 0</pose>
        <inertial>
        <pose>0 0 0 0 -0 0</pose>
        <mass>0.005</mass>
        <inertia>
            <ixx>9.75e-07</ixx>
            <ixy>0</ixy>
            <ixz>0</ixz>
            <iyy>4.17041e-05</iyy>
            <iyz>0</iyz>
            <izz>4.26041e-05</izz>
        </inertia>
        </inertial>
        <collision name='rotor_0_collision'>
        <pose>0 0 0 0 -0 0</pose>
        <geometry>
            <cylinder>
            <length>0.005</length>
            <radius>0.1</radius>
            </cylinder>
        </geometry>
        <surface>
            <contact>
            <ode/>
            </contact>
            <friction>
            <ode/>
            </friction>
        </surface>
        </collision>
        <visual name='rotor_0_visual'>
        <pose>0 0 0 0 -0 0</pose>
        <geometry>
            <mesh>
            <scale>0.1 0.1 0.1</scale>
            <uri>model://drone_cvar_racing/meshes/propeller_ccw.dae</uri>
            </mesh>
        </geometry>
        <material>
            <diffuse>0 0 1 1</diffuse>
            <script>
            <name>Gazebo/Blue</name>
            <uri>file://media/materials/scripts/gazebo.material</uri>
            </script>
        </material>
        <cast_shadows>0</cast_shadows>
        </visual>
        <gravity>1</gravity>
        <velocity_decay/>
    </link>
    <joint name='rotor_0_joint' type='revolute'>
        <child>rotor_0</child>
        <parent>base_link</parent>
        <axis>
        <xyz expressed_in='__model__'>0 0 1</xyz>
        <limit>
            <lower>-1e+16</lower>
            <upper>1e+16</upper>
        </limit>
        <dynamics>
            <spring_reference>0</spring_reference>
            <spring_stiffness>0</spring_stiffness>
        </dynamics>
        </axis>
    </joint>
    <link name='rotor_1'>
        <pose>-0.120981735 0.129737027 0.0 0 -0 0</pose>
        <inertial>
        <pose>0 0 0 0 -0 0</pose>
        <mass>0.005</mass>
        <inertia>
            <ixx>9.75e-07</ixx>
            <ixy>0</ixy>
            <ixz>0</ixz>
            <iyy>4.17041e-05</iyy>
            <iyz>0</iyz>
            <izz>4.26041e-05</izz>
        </inertia>
        </inertial>
        <collision name='rotor_1_collision'>
        <pose>0 0 0 0 -0 0</pose>
        <geometry>
            <cylinder>
            <length>0.005</length>
            <radius>0.1</radius>
            </cylinder>
        </geometry>
        <surface>
            <contact>
            <ode/>
            </contact>
            <friction>
            <ode/>
            </friction>
        </surface>
        </collision>
        <visual name='rotor_1_visual'>
        <pose>0 0 0 0 -0 0</pose>
        <geometry>
            <mesh>
            <scale>0.1 0.1 0.1</scale>
            <uri>model://drone_cvar_racing/meshes/propeller_ccw.dae</uri>
            </mesh>
        </geometry>
        <material>
            <diffuse>1 0 0 1</diffuse>
            <script>
            <name>Gazebo/Red</name>
            <uri>file://media/materials/scripts/gazebo.material</uri>
            </script>
        </material>
        <cast_shadows>0</cast_shadows>
        </visual>
        <gravity>1</gravity>
        <velocity_decay/>
    </link>
    <joint name='rotor_1_joint' type='revolute'>
        <child>rotor_1</child>
        <parent>base_link</parent>
        <axis>
        <xyz expressed_in='__model__'>0 0 1</xyz>
        <limit>
            <lower>-1e+16</lower>
            <upper>1e+16</upper>
        </limit>
        <dynamics>
            <spring_reference>0</spring_reference>
            <spring_stiffness>0</spring_stiffness>
        </dynamics>
        </axis>
    </joint>
    <link name='rotor_2'>
        <pose>0.143513952 0.104268989 0.0 0 -0 0</pose>
        <inertial>
        <pose>0 0 0 0 -0 0</pose>
        <mass>0.005</mass>
        <inertia>
            <ixx>9.75e-07</ixx>
            <ixy>0</ixy>
            <ixz>0</ixz>
            <iyy>4.17041e-05</iyy>
            <iyz>0</iyz>
            <izz>4.26041e-05</izz>
        </inertia>
        </inertial>
        <collision name='rotor_2_collision'>
        <pose>0 0 0 0 -0 0</pose>
        <geometry>
            <cylinder>
            <length>0.005</length>
            <radius>0.1</radius>
            </cylinder>
        </geometry>
        <surface>
            <contact>
            <ode/>
            </contact>
            <friction>
            <ode/>
            </friction>
        </surface>
        </collision>
        <visual name='rotor_2_visual'>
        <pose>0 0 0 0 -0 0</pose>
        <geometry>
            <mesh>
            <scale>0.1 0.1 0.1</scale>
            <uri>model://drone_cvar_racing/meshes/propeller_cw.dae</uri>
            </mesh>
        </geometry>
        <material>
            <diffuse>0 0 1 1</diffuse>
            <script>
            <name>Gazebo/Blue</name>
            <uri>file://media/materials/scripts/gazebo.material</uri>
            </script>
        </material>
        <cast_shadows>0</cast_shadows>
        </visual>
        <gravity>1</gravity>
        <velocity_decay/>
    </link>
    <joint name='rotor_2_joint' type='revolute'>
        <child>rotor_2</child>
        <parent>base_link</parent>
        <axis>
        <xyz expressed_in='__model__'>0 0 1</xyz>
        <limit>
            <lower>-1e+16</lower>
            <upper>1e+16</upper>
        </limit>
        <dynamics>
            <spring_reference>0</spring_reference>
            <spring_stiffness>0</spring_stiffness>
        </dynamics>
        </axis>
    </joint>
    <link name='rotor_3'>
        <pose>-0.120981735 -0.129737027 0.0 0 -0 0</pose>
        <inertial>
        <pose>0 0 0 0 -0 0</pose>
        <mass>0.005</mass>
        <inertia>
            <ixx>9.75e-07</ixx>
            <ixy>0</ixy>
            <ixz>0</ixz>
            <iyy>4.17041e-05</iyy>
            <iyz>0</iyz>
            <izz>4.26041e-05</izz>
        </inertia>
        </inertial>
        <collision name='rotor_3_collision'>
        <pose>0 0 0 0 -0 0</pose>
        <geometry>
            <cylinder>
            <length>0.005</length>
            <radius>0.1</radius>
            </cylinder>
        </geometry>
        <surface>
            <contact>
            <ode/>
            </contact>
            <friction>
            <ode/>
            </friction>
        </surface>
        </collision>
        <visual name='rotor_3_visual'>
        <pose>0 0 0 0 -0 0</pose>
        <geometry>
            <mesh>
            <scale>0.1 0.1 0.1</scale>
            <uri>model://drone_cvar_racing/meshes/propeller_cw.dae</uri>
            </mesh>
        </geometry>
        <material>
            <diffuse>1 0 0 1</diffuse>
            <script>
            <name>Gazebo/Red</name>
            <uri>file://media/materials/scripts/gazebo.material</uri>
            </script>
        </material>
        <cast_shadows>0</cast_shadows>
        </visual>
        <gravity>1</gravity>
        <velocity_decay/>
    </link>
    <joint name='rotor_3_joint' type='revolute'>
        <child>rotor_3</child>
        <parent>base_link</parent>
        <axis>
        <xyz expressed_in='__model__'>0 0 1</xyz>
        <limit>
            <lower>-1e+16</lower>
            <upper>1e+16</upper>
        </limit>
        <dynamics>
            <spring_reference>0</spring_reference>
            <spring_stiffness>0</spring_stiffness>
        </dynamics>
        </axis>
    </joint>

  </model>
</sdf>
